Workbook

Sheet Instrucciones
B2: Base de datos de revisión de literatura
B3: Modelo dinámico de vehículo aeroespacial con incertidumbres paramétricas + GNC + Monte Carlo + HIL
B6: 1. Base de datos
B7: Registra cada paper (una fila = un paper). El ID se genera solo al escribir el Título. Usa las listas desplegables en Estado, Tipo de publicación, Temas, Incertidumbres, Monte Carlo, Controlador, HIL y Calidad. Las columnas están agrupadas por sección (usa los botones '+ / -' sobre los encabezados para colapsar secciones que no estés usando).
B9: 2. Preguntas de investigación
B10: Guía de qué columnas de la Base de datos filtrar para responder cada pregunta clave de tu estado del arte.
B12: 3. Estadísticas
B13: Tablas y gráficos automáticos: papers por año, tema, tipo de publicación, institución, controlador e incertidumbre.
B15: 4. Estado de lectura
B16: Panel con conteos de Pendiente/Leyendo/Leído/Analizado, papers fundamentales y complementarios, y % de avance.
B18: 5. Resumen estado del arte
B19: Matriz comparativa (vinculada automáticamente a la Base de datos) lista para redactar el capítulo de estado del arte.
B22: Escalabilidad: la hoja 'Base de datos' incluye 150 filas listas para usar (Tabla de Excel 'BaseDatos'). Para agregar más papers, simplemente escribe en la fila siguiente a la última — Excel expande la tabla, el formato, las listas desplegables y el formato condicional automáticamente.

Sheet Base de datos
A1: ID | B1: Estado | C1: Título | D1: Autor principal | E1: Año | F1: Revista o Conferencia | G1: DOI | H1: Enlace | I1: Tipo de publicación | J1: País o Institución | K1: Tipo de vehículo | L1: Tema: Review | M1: Tema: Modelo dinámico | N1: Tema: Aerodinámica | O1: Tema: Propulsión | P1: Tema: Actuadores | Q1: Tema: Sensores | R1: Tema: Guidance | S1: Tema: Navigation | T1: Tema: Control | U1: Tema: GNC | V1: Tema: Robust Control | W1: Tema: Adaptive Control | X1: Tema: MPC | Y1: Tema: LQR | Z1: Tema: PID | AA1: Tema: Sliding Mode | AB1: Tema: H-infinito | AC1: Tema: Hardware-in-the-Loop | AD1: Tema: Monte Carlo | AE1: Tema: Análisis de sensibilidad | AF1: Tema: Uncertainty Quantification | AG1: Tema: Ingeniería de Sistemas | AH1: Tema: Arquitectura de Software | AI1: Tema: F Prime (F') | AJ1: Tema: ROS | AK1: Tema: cFS | AL1: Tema: Otros | AM1: Incert.: Masa | AN1: Incert.: Centro de gravedad | AO1: Incert.: Momentos de inercia | AP1: Incert.: Coeficientes aerodinámicos | AQ1: Incert.: Empuje | AR1: Incert.: Actuadores | AS1: Incert.: Sensores | AT1: Incert.: Viento | AU1: Incert.: Turbulencia | AV1: Incert.: Dinámicas no modeladas | AW1: Incert.: Otros | AX1: Parámetro(s) con incertidumbre | AY1: Magnitud utilizada (ej. ±5%, ±10 mm) | AZ1: Distribución | BA1: Justificación de los autores | BB1: ¿Usa Monte Carlo? | BC1: N° de simulaciones | BD1: Método de muestreo | BE1: Software utilizado (MC) | BF1: Variables perturbadas | BG1: Tipo de controlador | BH1: Modelo dinámico utilizado | BI1: Variables controladas | BJ1: Objetivo del controlador | BK1: Métricas utilizadas | BL1: Robustez evaluada | BM1: ¿Usa HIL? | BN1: Plataforma | BO1: Hardware | BP1: Software (HIL) | BQ1: Tiempo real | BR1: Objetivo HIL | BS1: Principal aporte | BT1: Limitaciones | BU1: Trabajos futuros | BV1: Ideas útiles para mi memoria | BW1: Relevancia (1-5) | BX1: Calidad metodológica (1-5) | BY1: ¿Lo citaré en la memoria? | BZ1: Prioridad de lectura
A2: =IF(C2="","",ROW()-1) -> 1 | B2: Analizado | C2: Robust Nonlinear Model Predictive Control for a Highly Maneuverable Aircraft | D2: Conrad, F. | E2: 2025 | F2: Journal of Guidance, Control, and Dynamics | G2: 10.2514/1.Gxxxxx | H2: https://doi.org/10.2514/1.Gxxxxx | I2: Journal | J2: DLR (Alemania) | K2: Aeronave ADMIRE (fighter-type) | T2: Sí | U2: Sí | X2: Sí | AP2: Sí | BB2: No | BG2: NMPC | BH2: 6-DOF no lineal (ADMIRE) | BM2: No | BS2: Formulación NMPC de doble lazo (interno/externo) con linealización por realimentación para maniobras agresivas. | BW2: 5 | BX2: 4 | BY2: Sí | BZ2: Alta
A3: =IF(C3="","",ROW()-1)
A4: =IF(C4="","",ROW()-1)
A5: =IF(C5="","",ROW()-1)
A6: =IF(C6="","",ROW()-1)
A7: =IF(C7="","",ROW()-1)
A8: =IF(C8="","",ROW()-1)
A9: =IF(C9="","",ROW()-1)
A10: =IF(C10="","",ROW()-1)
A11: =IF(C11="","",ROW()-1)
A12: =IF(C12="","",ROW()-1)
A13: =IF(C13="","",ROW()-1)
A14: =IF(C14="","",ROW()-1)
... A151: =IF(C151="","",ROW()-1)

Sheet Preguntas de investigación
B2: Preguntas de investigación — guía de filtrado
B3: Usa el Autofiltro de la hoja 'Base de datos' con las columnas indicadas para responder cada pregunta.
B5: Pregunta de investigación | C5: Columnas relevantes en 'Base de datos' | D5: Cómo filtrar / qué buscar | E5: IDs de papers relevantes | F5: Notas
B6: ¿Qué incertidumbres usan? | C6: AM:AW (Incert.: ...) | D6: Filtra por 'Sí' en la(s) columna(s) del tipo de incertidumbre de interés.
B7: ¿Qué magnitud utilizan? | C7: AX, AY (Parámetro / Magnitud utilizada) | D7: Lee directamente el texto de la columna 'Magnitud utilizada'.
B8: ¿Qué distribución utilizan? | C8: AZ (Distribución) | D8: Filtra por el valor de la lista desplegable (Normal, Uniforme, etc.).
B9: ¿Cómo implementan Monte Carlo? | C9: BB:BF (Usa MC, N° simulaciones, Método, Software, Variables) | D9: Filtra BB='Sí' y revisa BC-BF para el detalle del método.
B10: ¿Qué controlador utilizan? | C10: BG (Tipo de controlador) | D10: Filtra por el tipo de controlador de la lista desplegable.
B11: ¿Cómo validan el modelo? | C11: BH, BS (Modelo dinámico utilizado, Principal aporte) | D11: Revisa el texto libre de estas columnas; complementa con BL (Robustez evaluada).
B12: ¿Usan HIL? | C12: BM:BR (Usa HIL, Plataforma, Hardware, Software, Tiempo real, Objetivo) | D12: Filtra BM='Sí' para ver solo papers con validación HIL.
B13: ¿Qué métricas utilizan? | C13: BK (Métricas utilizadas) | D13: Lee el texto libre de la columna de métricas.

Sheet Estadísticas
B2: Estadísticas de la revisión de literatura
B3: Las tablas se calculan automáticamente a partir de 'Base de datos'. Los gráficos se actualizan solos.
B5: Papers por año (período) | E5: Papers por tema | H5: Papers por tipo de publicación | K5: Papers por institución (editable)
B6: Categoría | C6: N° de papers | E6: Categoría | F6: N° de papers | H6: Categoría | I6: N° de papers | K6: Institución (edítalo) | L6: N° de papers
B7: <1990 | C7: =COUNTIFS('Base de datos'!$E$2:$E$151,"<1990") -> 0 | E7: Review | F7: =COUNTIF('Base de datos'!$L$2:$L$151,"Sí") -> 0 | H7: Journal | I7: =COUNTIF('Base de datos'!$I$2:$I$151,"Journal") -> 1 | K7: NASA | L7: =COUNTIF('Base de datos'!$J$2:$J$151,"*"&$K7&"*") -> 0
B8: 1990-1999 | C8: =COUNTIFS('Base de datos'!$E$2:$E$151,">="&1990,'Base de datos'!$E$2:$E$151,"<="&1999) -> 0 | E8: Modelo dinámico | F8: =COUNTIF('Base de datos'!$M$2:$M$151,"Sí") -> 0 | H8: Conference | I8: =COUNTIF('Base de datos'!$I$2:$I$151,"Conference") -> 0 | K8: ESA | L8: =COUNTIF('Base de datos'!$J$2:$J$151,"*"&$K8&"*") -> 0
B9: 2000-2009 | C9: =COUNTIFS('Base de datos'!$E$2:$E$151,">="&2000,'Base de datos'!$E$2:$E$151,"<="&2009) -> 0 | E9: Aerodinámica | F9: =COUNTIF('Base de datos'!$N$2:$N$151,"Sí") -> 0 | H9: Thesis | I9: =COUNTIF('Base de datos'!$I$2:$I$151,"Thesis") -> 0 | K9: JAXA | L9: =COUNTIF('Base de datos'!$J$2:$J$151,"*"&$K9&"*") -> 0
B10: 2010-2019 | C10: =COUNTIFS('Base de datos'!$E$2:$E$151,">="&2010,'Base de datos'!$E$2:$E$151,"<="&2019) -> 0 | E10: Propulsión | F10: =COUNTIF('Base de datos'!$O$2:$O$151,"Sí") -> 0 | H10: Report | I10: =COUNTIF('Base de datos'!$I$2:$I$151,"Report") -> 0 | K10: DLR | L10: =COUNTIF('Base de datos'!$J$2:$J$151,"*"&$K10&"*") -> 1
B11: 2020-2029 | C11: =COUNTIFS('Base de datos'!$E$2:$E$151,">="&2020,'Base de datos'!$E$2:$E$151,"<="&2029) -> 1 | E11: Actuadores | F11: =COUNTIF('Base de datos'!$P$2:$P$151,"Sí") -> 0 | H11: Book | I11: =COUNTIF('Base de datos'!$I$2:$I$151,"Book") -> 0 | K11: Universidad | L11: =COUNTIF('Base de datos'!$J$2:$J$151,"*"&$K11&"*") -> 0
B12: 2030+ | C12: =COUNTIFS('Base de datos'!$E$2:$E$151,">=2030") -> 0 | E12: Sensores | F12: =COUNTIF('Base de datos'!$Q$2:$Q$151,"Sí") -> 0 | H12: Review | I12: =COUNTIF('Base de datos'!$I$2:$I$151,"Review") -> 0 | K12: Otro | L12: =COUNTIF('Base de datos'!$J$2:$J$151,"*"&$K12&"*") -> 0
E13: Guidance | F13: =COUNTIF('Base de datos'!$R$2:$R$151,"Sí") -> 0
E14: Navigation | F14: =COUNTIF('Base de datos'!$S$2:$S$151,"Sí") -> 0
E15: Control | F15: =COUNTIF('Base de datos'!$T$2:$T$151,"Sí") -> 1
E16: GNC | F16: =COUNTIF('Base de datos'!$U$2:$U$151,"Sí") -> 1
E17: Robust Control | F17: =COUNTIF('Base de datos'!$V$2:$V$151,"Sí") -> 0
E18: Adaptive Control | F18: =COUNTIF('Base de datos'!$W$2:$W$151,"Sí") -> 0
E19: MPC | F19: =COUNTIF('Base de datos'!$X$2:$X$151,"Sí") -> 1
E20: LQR | F20: =COUNTIF('Base de datos'!$Y$2:$Y$151,"Sí") -> 0
E21: PID | F21: =COUNTIF('Base de datos'!$Z$2:$Z$151,"Sí") -> 0
E22: Sliding Mode | F22: =COUNTIF('Base de datos'!$AA$2:$AA$151,"Sí") -> 0
E23: H-infinito | F23: =COUNTIF('Base de datos'!$AB$2:$AB$151,"Sí") -> 0
E24: Hardware-in-the-Loop | F24: =COUNTIF('Base de datos'!$AC$2:$AC$151,"Sí") -> 0
B25: Papers por tipo de controlador
B26: Categoría | C26: N° de papers
B27: PID | C27: =COUNTIF('Base de datos'!$BG$2:$BG$151,"PID") -> 0 | E27: Papers por tipo de incertidumbre
B28: LQR | C28: =COUNTIF('Base de datos'!$BG$2:$BG$151,"LQR") -> 0 | E28: Categoría | F28: N° de papers
B29: LQG | C29: =COUNTIF('Base de datos'!$BG$2:$BG$151,"LQG") -> 0 | E29: Masa | F29: =COUNTIF('Base de datos'!$AM$2:$AM$151,"Sí") -> 0
B30: MPC | C30: =COUNTIF('Base de datos'!$BG$2:$BG$151,"MPC") -> 0 | E30: Centro de gravedad | F30: =COUNTIF('Base de datos'!$AN$2:$AN$151,"Sí") -> 0
B31: NMPC | C31: =COUNTIF('Base de datos'!$BG$2:$BG$151,"NMPC") -> 1 | E31: Momentos de inercia | F31: =COUNTIF('Base de datos'!$AO$2:$AO$151,"Sí") -> 0
B32: Sliding Mode | C32: =COUNTIF('Base de datos'!$BG$2:$BG$151,"Sliding Mode") -> 0 | E32: Coeficientes aerodinámicos | F32: =COUNTIF('Base de datos'!$AP$2:$AP$151,"Sí") -> 1
B33: H-infinito | C33: =COUNTIF('Base de datos'!$BG$2:$BG$151,"H-infinito") -> 0 | E33: Empuje | F33: =COUNTIF('Base de datos'!$AQ$2:$AQ$151,"Sí") -> 0
B34: Adaptativo | C34: =COUNTIF('Base de datos'!$BG$2:$BG$151,"Adaptativo") -> 0 | E34: Actuadores | F34: =COUNTIF('Base de datos'!$AR$2:$AR$151,"Sí") -> 0
B35: Robusto (mu-synthesis) | C35: =COUNTIF('Base de datos'!$BG$2:$BG$151,"Robusto (mu-synthesis)") -> 0 | E35: Sensores | F35: =COUNTIF('Base de datos'!$AS$2:$AS$151,"Sí") -> 0
B36: Backstepping | C36: =COUNTIF('Base de datos'!$BG$2:$BG$151,"Backstepping") -> 0 | E36: Viento | F36: =COUNTIF('Base de datos'!$AT$2:$AT$151,"Sí") -> 0
B37: Gain Scheduling | C37: =COUNTIF('Base de datos'!$BG$2:$BG$151,"Gain Scheduling") -> 0 | E37: Turbulencia | F37: =COUNTIF('Base de datos'!$AU$2:$AU$151,"Sí") -> 0
B38: Ninguno / No aplica | C38: =COUNTIF('Base de datos'!$BG$2:$BG$151,"Ninguno / No aplica") -> 0 | E38: Dinámicas no modeladas | F38: =COUNTIF('Base de datos'!$AV$2:$AV$151,"Sí") -> 0
B39: Otro | C39: =COUNTIF('Base de datos'!$BG$2:$BG$151,"Otro") -> 0 | E39: Otros | F39: =COUNTIF('Base de datos'!$AW$2:$AW$151,"Sí") -> 0

Sheet Estado de lectura
B2: Panel de estado de lectura
B3: Indicadores calculados automáticamente desde 'Base de datos'.
B5: Total papers | D5: Pendiente | F5: Leyendo | H5: Leído | J5: Analizado | L5: Papers fundamentales (Relevancia=5 y citaré=Sí) | N5: Papers complementarios (Relevancia<=2)
B6: =COUNTIF('Base de datos'!$C$2:$C$151,"<>") -> 1 | D6: =COUNTIF('Base de datos'!$B$2:$B$151,"Pendiente") -> 0 | F6: =COUNTIF('Base de datos'!$B$2:$B$151,"Leyendo") -> 0 | H6: =COUNTIF('Base de datos'!$B$2:$B$151,"Leído") -> 0 | J6: =COUNTIF('Base de datos'!$B$2:$B$151,"Analizado") -> 1 | L6: =COUNTIFS('Base de datos'!$BW$2:$BW$151,"5",'Base de datos'!$BY$2:$BY$151,"Sí") -> 1 | N6: =COUNTIFS('Base de datos'!$BW$2:$BW$151,"1")+COUNTIFS('Base de datos'!$BW$2:$BW$151,"2") -> 0
B9: % de papers Analizados | D9: =IFERROR(COUNTIF('Base de datos'!$B$2:$B$151,"Analizado")/COUNTIF('Base de datos'!$C$2:$C$151,"<>"),0) -> 1
B12: Distribución por estado
B13: Estado | C13: N° de papers
B14: Pendiente | C14: =COUNTIF('Base de datos'!$B$2:$B$151,"Pendiente") -> 0
B15: Leyendo | C15: =COUNTIF('Base de datos'!$B$2:$B$151,"Leyendo") -> 0
B16: Leído | C16: =COUNTIF('Base de datos'!$B$2:$B$151,"Leído") -> 0
B17: Analizado | C17: =COUNTIF('Base de datos'!$B$2:$B$151,"Analizado") -> 1
B20: Sugerencia: usa el filtro de la columna 'Estado' en la hoja 'Base de datos' para ver el listado completo de cada categoría (Pendiente, Leyendo, Leído, Analizado).

Sheet Resumen estado del arte
A1: ID | B1: Título | C1: Tipo de vehículo | D1: Modelo dinámico | E1: Incertidumbres consideradas | F1: Magnitud | G1: Distribución | H1: Monte Carlo | I1: Controlador | J1: Validación | K1: HIL | L1: Principal contribución
A2: =IF('Base de datos'!A2="","",'Base de datos'!A2) -> 1 | B2: =IF('Base de datos'!C2="","",'Base de datos'!C2) -> Robust Nonlinear Model Predictive Control for a Highly Maneuverable Aircraft | C2: =IF('Base de datos'!K2="","",'Base de datos'!K2) -> Aeronave ADMIRE (fighter-type) | D2: =IF('Base de datos'!BH2="","",'Base de datos'!BH2) -> 6-DOF no lineal (ADMIRE) | E2: =_xlfn.TEXTJOIN(", ",TRUE(),IF('Base de datos'!$AM$2="Sí","Masa",""),IF('Base de datos'!$AN$2="Sí","Centro de gravedad",""),IF('Base de datos'!$AO$2="Sí","Momentos de inercia",""),IF('Base de datos'!$AP$2="Sí","Coeficientes aerodinámicos",""),IF('Base de datos'!$AQ$2="Sí","Empuje",""),IF('Base de datos'!$AR$2="Sí","Actuadores",""),IF('Base de datos'!$AS$2="Sí","Sensores",""),IF('Base de datos'!$AT$2="Sí","Viento",""),IF('Base de datos'!$AU$2="Sí","Turbulencia",""),IF('Base de datos'!$AV$2="Sí","Dinámicas no modeladas",""),IF('Base de datos'!$AW$2="Sí","Otros","")) -> Coeficientes aerodinámicos | F2: =IF('Base de datos'!AY2="","",'Base de datos'!AY2) | G2: =IF('Base de datos'!AZ2="","",'Base de datos'!AZ2) | H2: =IF('Base de datos'!BB2="Sí","Sí ("&'Base de datos'!BD2&", n="&'Base de datos'!BC2&")",IF('Base de datos'!BB2="","",'Base de datos'!BB2)) -> No | I2: =IF('Base de datos'!BG2="","",'Base de datos'!BG2) -> NMPC | J2: =_xlfn.TEXTJOIN(", ",TRUE(),IF('Base de datos'!BB2="Sí","Monte Carlo",""),IF('Base de datos'!BM2="Sí","HIL",""),IF('Base de datos'!BL2="Sí","Robustez analítica","")) | K2: =IF('Base de datos'!BM2="","",'Base de datos'!BM2) -> No | L2: =IF('Base de datos'!BS2="","",'Base de datos'!BS2) -> Formulación NMPC de doble lazo (interno/externo) con linealización por realimentación para maniobras agresivas.
A3: =IF('Base de datos'!A3="","",'Base de datos'!A3) | B3: =IF('Base de datos'!C3="","",'Base de datos'!C3) | C3: =IF('Base de datos'!K3="","",'Base de datos'!K3) | D3: =IF('Base de datos'!BH3="","",'Base de datos'!BH3) | E3: =_xlfn.TEXTJOIN(", ",TRUE(),IF('Base de datos'!$AM$3="Sí","Masa",""),IF('Base de datos'!$AN$3="Sí","Centro de gravedad",""),IF('Base de datos'!$AO$3="Sí","Momentos de inercia",""),IF('Base de datos'!$AP$3="Sí","Coeficientes aerodinámicos",""),IF('Base de datos'!$AQ$3="Sí","Empuje",""),IF('Base de datos'!$AR$3="Sí","Actuadores",""),IF('Base de datos'!$AS$3="Sí","Sensores",""),IF('Base de datos'!$AT$3="Sí","Viento",""),IF('Base de datos'!$AU$3="Sí","Turbulencia",""),IF('Base de datos'!$AV$3="Sí","Dinámicas no modeladas",""),IF('Base de datos'!$AW$3="Sí","Otros","")) | F3: =IF('Base de datos'!AY3="","",'Base de datos'!AY3) | G3: =IF('Base de datos'!AZ3="","",'Base de datos'!AZ3) | H3: =IF('Base de datos'!BB3="Sí","Sí ("&'Base de datos'!BD3&", n="&'Base de datos'!BC3&")",IF('Base de datos'!BB3="","",'Base de datos'!BB3)) | I3: =IF('Base de datos'!BG3="","",'Base de datos'!BG3) | J3: =_xlfn.TEXTJOIN(", ",TRUE(),IF('Base de datos'!BB3="Sí","Monte Carlo",""),IF('Base de datos'!BM3="Sí","HIL",""),IF('Base de datos'!BL3="Sí","Robustez analítica","")) | K3: =IF('Base de datos'!BM3="","",'Base de datos'!BM3) | L3: =IF('Base de datos'!BS3="","",'Base de datos'!BS3)
A4: =IF('Base de datos'!A4="","",'Base de datos'!A4) | B4: =IF('Base de datos'!C4="","",'Base de datos'!C4) | C4: =IF('Base de datos'!K4="","",'Base de datos'!K4) | D4: =IF('Base de datos'!BH4="","",'Base de datos'!BH4) | E4: =_xlfn.TEXTJOIN(", ",TRUE(),IF('Base de datos'!$AM$4="Sí","Masa",""),IF('Base de datos'!$AN$4="Sí","Centro de gravedad",""),IF('Base de datos'!$AO$4="Sí","Momentos de inercia",""),IF('Base de datos'!$AP$4="Sí","Coeficientes aerodinámicos",""),IF('Base de datos'!$AQ$4="Sí","Empuje",""),IF('Base de datos'!$AR$4="Sí","Actuadores",""),IF('Base de datos'!$AS$4="Sí","Sensores",""),IF('Base de datos'!$AT$4="Sí","Viento",""),IF('Base de datos'!$AU$4="Sí","Turbulencia",""),IF('Base de datos'!$AV$4="Sí","Dinámicas no modeladas",""),IF('Base de datos'!$AW$4="Sí","Otros","")) | F4: =IF('Base de datos'!AY4="","",'Base de datos'!AY4) | G4: =IF('Base de datos'!AZ4="","",'Base de datos'!AZ4) | H4: =IF('Base de datos'!BB4="Sí","Sí ("&'Base de datos'!BD4&", n="&'Base de datos'!BC4&")",IF('Base de datos'!BB4="","",'Base de datos'!BB4)) | I4: =IF('Base de datos'!BG4="","",'Base de datos'!BG4) | J4: =_xlfn.TEXTJOIN(", ",TRUE(),IF('Base de datos'!BB4="Sí","Monte Carlo",""),IF('Base de datos'!BM4="Sí","HIL",""),IF('Base de datos'!BL4="Sí","Robustez analítica","")) | K4: =IF('Base de datos'!BM4="","",'Base de datos'!BM4) | L4: =IF('Base de datos'!BS4="","",'Base de datos'!BS4)
A5: =IF('Base de datos'!A5="","",'Base de datos'!A5) | B5: =IF('Base de datos'!C5="","",'Base de datos'!C5) | C5: =IF('Base de datos'!K5="","",'Base de datos'!K5) | D5: =IF('Base de datos'!BH5="","",'Base de datos'!BH5) | E5: =_xlfn.TEXTJOIN(", ",TRUE(),IF('Base de datos'!$AM$5="Sí","Masa",""),IF('Base de datos'!$AN$5="Sí","Centro de gravedad",""),IF('Base de datos'!$AO$5="Sí","Momentos de inercia",""),IF('Base de datos'!$AP$5="Sí","Coeficientes aerodinámicos",""),IF('Base de datos'!$AQ$5="Sí","Empuje",""),IF('Base de datos'!$AR$5="Sí","Actuadores",""),IF('Base de datos'!$AS$5="Sí","Sensores",""),IF('Base de datos'!$AT$5="Sí","Viento",""),IF('Base de datos'!$AU$5="Sí","Turbulencia",""),IF('Base de datos'!$AV$5="Sí","Dinámicas no modeladas",""),IF('Base de datos'!$AW$5="Sí","Otros","")) | F5: =IF('Base de datos'!AY5="","",'Base de datos'!AY5) | G5: =IF('Base de datos'!AZ5="","",'Base de datos'!AZ5) | H5: =IF('Base de datos'!BB5="Sí","Sí ("&'Base de datos'!BD5&", n="&'Base de datos'!BC5&")",IF('Base de datos'!BB5="","",'Base de datos'!BB5)) | I5: =IF('Base de datos'!BG5="","",'Base de datos'!BG5) | J5: =_xlfn.TEXTJOIN(", ",TRUE(),IF('Base de datos'!BB5="Sí","Monte Carlo",""),IF('Base de datos'!BM5="Sí","HIL",""),IF('Base de datos'!BL5="Sí","Robustez analítica","")) | K5: =IF('Base de datos'!BM5="","",'Base de datos'!BM5) | L5: =IF('Base de datos'!BS5="","",'Base de datos'!BS5)
A6: =IF('Base de datos'!A6="","",'Base de datos'!A6) | B6: =IF('Base de datos'!C6="","",'Base de datos'!C6) | C6: =IF('Base de datos'!K6="","",'Base de datos'!K6) | D6: =IF('Base de datos'!BH6="","",'Base de datos'!BH6) | E6: =_xlfn.TEXTJOIN(", ",TRUE(),IF('Base de datos'!$AM$6="Sí","Masa",""),IF('Base de datos'!$AN$6="Sí","Centro de gravedad",""),IF('Base de datos'!$AO$6="Sí","Momentos de inercia",""),IF('Base de datos'!$AP$6="Sí","Coeficientes aerodinámicos",""),IF('Base de datos'!$AQ$6="Sí","Empuje",""),IF('Base de datos'!$AR$6="Sí","Actuadores",""),IF('Base de datos'!$AS$6="Sí","Sensores",""),IF('Base de datos'!$AT$6="Sí","Viento",""),IF('Base de datos'!$AU$6="Sí","Turbulencia",""),IF('Base de datos'!$AV$6="Sí","Dinámicas no modeladas",""),IF('Base de datos'!$AW$6="Sí","Otros","")) | F6: =IF('Base de datos'!AY6="","",'Base de datos'!AY6) | G6: =IF('Base de datos'!AZ6="","",'Base de datos'!AZ6) | H6: =IF('Base de datos'!BB6="Sí","Sí ("&'Base de datos'!BD6&", n="&'Base de datos'!BC6&")",IF('Base de datos'!BB6="","",'Base de datos'!BB6)) | I6: =IF('Base de datos'!BG6="","",'Base de datos'!BG6) | J6: =_xlfn.TEXTJOIN(", ",TRUE(),IF('Base de datos'!BB6="Sí","Monte Carlo",""),IF('Base de datos'!BM6="Sí","HIL",""),IF('Base de datos'!BL6="Sí","Robustez analítica","")) | K6: =IF('Base de datos'!BM6="","",'Base de datos'!BM6) | L6: =IF('Base de datos'!BS6="","",'Base de datos'!BS6)
A7: =IF('Base de datos'!A7="","",'Base de datos'!A7) | B7: =IF('Base de datos'!C7="","",'Base de datos'!C7) | C7: =IF('Base de datos'!K7="","",'Base de datos'!K7) | D7: =IF('Base de datos'!BH7="","",'Base de datos'!BH7) | E7: =_xlfn.TEXTJOIN(", ",TRUE(),IF('Base de datos'!$AM$7="Sí","Masa",""),IF('Base de datos'!$AN$7="Sí","Centro de gravedad",""),IF('Base de datos'!$AO$7="Sí","Momentos de inercia",""),IF('Base de datos'!$AP$7="Sí","Coeficientes aerodinámicos",""),IF('Base de datos'!$AQ$7="Sí","Empuje",""),IF('Base de datos'!$AR$7="Sí","Actuadores",""),IF('Base de datos'!$AS$7="Sí","Sensores",""),IF('Base de datos'!$AT$7="Sí","Viento",""),IF('Base de datos'!$AU$7="Sí","Turbulencia",""),IF('Base de datos'!$AV$7="Sí","Dinámicas no modeladas",""),IF('Base de datos'!$AW$7="Sí","Otros","")) | F7: =IF('Base de datos'!AY7="","",'Base de datos'!AY7) | G7: =IF('Base de datos'!AZ7="","",'Base de datos'!AZ7) | H7: =IF('Base de datos'!BB7="Sí","Sí ("&'Base de datos'!BD7&", n="&'Base de datos'!BC7&")",IF('Base de datos'!BB7="","",'Base de datos'!BB7)) | I7: =IF('Base de datos'!BG7="","",'Base de datos'!BG7) | J7: =_xlfn.TEXTJOIN(", ",TRUE(),IF('Base de datos'!BB7="Sí","Monte Carlo",""),IF('Base de datos'!BM7="Sí","HIL",""),IF('Base de datos'!BL7="Sí","Robustez analítica","")) | K7: =IF('Base de datos'!BM7="","",'Base de datos'!BM7) | L7: =IF('Base de datos'!BS7="","",'Base de datos'!BS7)
A8: =IF('Base de datos'!A8="","",'Base de datos'!A8) | B8: =IF('Base de datos'!C8="","",'Base de datos'!C8) | C8: =IF('Base de datos'!K8="","",'Base de datos'!K8) | D8: =IF('Base de datos'!BH8="","",'Base de datos'!BH8) | E8: =_xlfn.TEXTJOIN(", ",TRUE(),IF('Base de datos'!$AM$8="Sí","Masa",""),IF('Base de datos'!$AN$8="Sí","Centro de gravedad",""),IF('Base de datos'!$AO$8="Sí","Momentos de inercia",""),IF('Base de datos'!$AP$8="Sí","Coeficientes aerodinámicos",""),IF('Base de datos'!$AQ$8="Sí","Empuje",""),IF('Base de datos'!$AR$8="Sí","Actuadores",""),IF('Base de datos'!$AS$8="Sí","Sensores",""),IF('Base de datos'!$AT$8="Sí","Viento",""),IF('Base de datos'!$AU$8="Sí","Turbulencia",""),IF('Base de datos'!$AV$8="Sí","Dinámicas no modeladas",""),IF('Base de datos'!$AW$8="Sí","Otros","")) | F8: =IF('Base de datos'!AY8="","",'Base de datos'!AY8) | G8: =IF('Base de datos'!AZ8="","",'Base de datos'!AZ8) | H8: =IF('Base de datos'!BB8="Sí","Sí ("&'Base de datos'!BD8&", n="&'Base de datos'!BC8&")",IF('Base de datos'!BB8="","",'Base de datos'!BB8)) | I8: =IF('Base de datos'!BG8="","",'Base de datos'!BG8) | J8: =_xlfn.TEXTJOIN(", ",TRUE(),IF('Base de datos'!BB8="Sí","Monte Carlo",""),IF('Base de datos'!BM8="Sí","HIL",""),IF('Base de datos'!BL8="Sí","Robustez analítica","")) | K8: =IF('Base de datos'!BM8="","",'Base de datos'!BM8) | L8: =IF('Base de datos'!BS8="","",'Base de datos'!BS8)
A9: =IF('Base de datos'!A9="","",'Base de datos'!A9) | B9: =IF('Base de datos'!C9="","",'Base de datos'!C9) | C9: =IF('Base de datos'!K9="","",'Base de datos'!K9) | D9: =IF('Base de datos'!BH9="","",'Base de datos'!BH9) | E9: =_xlfn.TEXTJOIN(", ",TRUE(),IF('Base de datos'!$AM$9="Sí","Masa",""),IF('Base de datos'!$AN$9="Sí","Centro de gravedad",""),IF('Base de datos'!$AO$9="Sí","Momentos de inercia",""),IF('Base de datos'!$AP$9="Sí","Coeficientes aerodinámicos",""),IF('Base de datos'!$AQ$9="Sí","Empuje",""),IF('Base de datos'!$AR$9="Sí","Actuadores",""),IF('Base de datos'!$AS$9="Sí","Sensores",""),IF('Base de datos'!$AT$9="Sí","Viento",""),IF('Base de datos'!$AU$9="Sí","Turbulencia",""),IF('Base de datos'!$AV$9="Sí","Dinámicas no modeladas",""),IF('Base de datos'!$AW$9="Sí","Otros","")) | F9: =IF('Base de datos'!AY9="","",'Base de datos'!AY9) | G9: =IF('Base de datos'!AZ9="","",'Base de datos'!AZ9) | H9: =IF('Base de datos'!BB9="Sí","Sí ("&'Base de datos'!BD9&", n="&'Base de datos'!BC9&")",IF('Base de datos'!BB9="","",'Base de datos'!BB9)) | I9: =IF('Base de datos'!BG9="","",'Base de datos'!BG9) | J9: =_xlfn.TEXTJOIN(", ",TRUE(),IF('Base de datos'!BB9="Sí","Monte Carlo",""),IF('Base de datos'!BM9="Sí","HIL",""),IF('Base de datos'!BL9="Sí","Robustez analítica","")) | K9: =IF('Base de datos'!BM9="","",'Base de datos'!BM9) | L9: =IF('Base de datos'!BS9="","",'Base de datos'!BS9)
A10: =IF('Base de datos'!A10="","",'Base de datos'!A10) | B10: =IF('Base de datos'!C10="","",'Base de datos'!C10) | C10: =IF('Base de datos'!K10="","",'Base de datos'!K10) | D10: =IF('Base de datos'!BH10="","",'Base de datos'!BH10) | E10: =_xlfn.TEXTJOIN(", ",TRUE(),IF('Base de datos'!$AM$10="Sí","Masa",""),IF('Base de datos'!$AN$10="Sí","Centro de gravedad",""),IF('Base de datos'!$AO$10="Sí","Momentos de inercia",""),IF('Base de datos'!$AP$10="Sí","Coeficientes aerodinámicos",""),IF('Base de datos'!$AQ$10="Sí","Empuje",""),IF('Base de datos'!$AR$10="Sí","Actuadores",""),IF('Base de datos'!$AS$10="Sí","Sensores",""),IF('Base de datos'!$AT$10="Sí","Viento",""),IF('Base de datos'!$AU$10="Sí","Turbulencia",""),IF('Base de datos'!$AV$10="Sí","Dinámicas no modeladas",""),IF('Base de datos'!$AW$10="Sí","Otros","")) | F10: =IF('Base de datos'!AY10="","",'Base de datos'!AY10) | G10: =IF('Base de datos'!AZ10="","",'Base de datos'!AZ10) | H10: =IF('Base de datos'!BB10="Sí","Sí ("&'Base de datos'!BD10&", n="&'Base de datos'!BC10&")",IF('Base de datos'!BB10="","",'Base de datos'!BB10)) | I10: =IF('Base de datos'!BG10="","",'Base de datos'!BG10) | J10: =_xlfn.TEXTJOIN(", ",TRUE(),IF('Base de datos'!BB10="Sí","Monte Carlo",""),IF('Base de datos'!BM10="Sí","HIL",""),IF('Base de datos'!BL10="Sí","Robustez analítica","")) | K10: =IF('Base de datos'!BM10="","",'Base de datos'!BM10) | L10: =IF('Base de datos'!BS10="","",'Base de datos'!BS10)
A11: =IF('Base de datos'!A11="","",'Base de datos'!A11) | B11: =IF('Base de datos'!C11="","",'Base de datos'!C11) | C11: =IF('Base de datos'!K11="","",'Base de datos'!K11) | D11: =IF('Base de datos'!BH11="","",'Base de datos'!BH11) | E11: =_xlfn.TEXTJOIN(", ",TRUE(),IF('Base de datos'!$AM$11="Sí","Masa",""),IF('Base de datos'!$AN$11="Sí","Centro de gravedad",""),IF('Base de datos'!$AO$11="Sí","Momentos de inercia",""),IF('Base de datos'!$AP$11="Sí","Coeficientes aerodinámicos",""),IF('Base de datos'!$AQ$11="Sí","Empuje",""),IF('Base de datos'!$AR$11="Sí","Actuadores",""),IF('Base de datos'!$AS$11="Sí","Sensores",""),IF('Base de datos'!$AT$11="Sí","Viento",""),IF('Base de datos'!$AU$11="Sí","Turbulencia",""),IF('Base de datos'!$AV$11="Sí","Dinámicas no modeladas",""),IF('Base de datos'!$AW$11="Sí","Otros","")) | F11: =IF('Base de datos'!AY11="","",'Base de datos'!AY11) | G11: =IF('Base de datos'!AZ11="","",'Base de datos'!AZ11) | H11: =IF('Base de datos'!BB11="Sí","Sí ("&'Base de datos'!BD11&", n="&'Base de datos'!BC11&")",IF('Base de datos'!BB11="","",'Base de datos'!BB11)) | I11: =IF('Base de datos'!BG11="","",'Base de datos'!BG11) | J11: =_xlfn.TEXTJOIN(", ",TRUE(),IF('Base de datos'!BB11="Sí","Monte Carlo",""),IF('Base de datos'!BM11="Sí","HIL",""),IF('Base de datos'!BL11="Sí","Robustez analítica","")) | K11: =IF('Base de datos'!BM11="","",'Base de datos'!BM11) | L11: =IF('Base de datos'!BS11="","",'Base de datos'!BS11)
A12: =IF('Base de datos'!A12="","",'Base de datos'!A12) | B12: =IF('Base de datos'!C12="","",'Base de datos'!C12) | C12: =IF('Base de datos'!K12="","",'Base de datos'!K12) | D12: =IF('Base de datos'!BH12="","",'Base de datos'!BH12) | E12: =_xlfn.TEXTJOIN(", ",TRUE(),IF('Base de datos'!$AM$12="Sí","Masa",""),IF('Base de datos'!$AN$12="Sí","Centro de gravedad",""),IF('Base de datos'!$AO$12="Sí","Momentos de inercia",""),IF('Base de datos'!$AP$12="Sí","Coeficientes aerodinámicos",""),IF('Base de datos'!$AQ$12="Sí","Empuje",""),IF('Base de datos'!$AR$12="Sí","Actuadores",""),IF('Base de datos'!$AS$12="Sí","Sensores",""),IF('Base de datos'!$AT$12="Sí","Viento",""),IF('Base de datos'!$AU$12="Sí","Turbulencia",""),IF('Base de datos'!$AV$12="Sí","Dinámicas no modeladas",""),IF('Base de datos'!$AW$12="Sí","Otros","")) | F12: =IF('Base de datos'!AY12="","",'Base de datos'!AY12) | G12: =IF('Base de datos'!AZ12="","",'Base de datos'!AZ12) | H12: =IF('Base de datos'!BB12="Sí","Sí ("&'Base de datos'!BD12&", n="&'Base de datos'!BC12&")",IF('Base de datos'!BB12="","",'Base de datos'!BB12)) | I12: =IF('Base de datos'!BG12="","",'Base de datos'!BG12) | J12: =_xlfn.TEXTJOIN(", ",TRUE(),IF('Base de datos'!BB12="Sí","Monte Carlo",""),IF('Base de datos'!BM12="Sí","HIL",""),IF('Base de datos'!BL12="Sí","Robustez analítica","")) | K12: =IF('Base de datos'!BM12="","",'Base de datos'!BM12) | L12: =IF('Base de datos'!BS12="","",'Base de datos'!BS12)
A13: =IF('Base de datos'!A13="","",'Base de datos'!A13) | B13: =IF('Base de datos'!C13="","",'Base de datos'!C13) | C13: =IF('Base de datos'!K13="","",'Base de datos'!K13) | D13: =IF('Base de datos'!BH13="","",'Base de datos'!BH13) | E13: =_xlfn.TEXTJOIN(", ",TRUE(),IF('Base de datos'!$AM$13="Sí","Masa",""),IF('Base de datos'!$AN$13="Sí","Centro de gravedad",""),IF('Base de datos'!$AO$13="Sí","Momentos de inercia",""),IF('Base de datos'!$AP$13="Sí","Coeficientes aerodinámicos",""),IF('Base de datos'!$AQ$13="Sí","Empuje",""),IF('Base de datos'!$AR$13="Sí","Actuadores",""),IF('Base de datos'!$AS$13="Sí","Sensores",""),IF('Base de datos'!$AT$13="Sí","Viento",""),IF('Base de datos'!$AU$13="Sí","Turbulencia",""),IF('Base de datos'!$AV$13="Sí","Dinámicas no modeladas",""),IF('Base de datos'!$AW$13="Sí","Otros","")) | F13: =IF('Base de datos'!AY13="","",'Base de datos'!AY13) | G13: =IF('Base de datos'!AZ13="","",'Base de datos'!AZ13) | H13: =IF('Base de datos'!BB13="Sí","Sí ("&'Base de datos'!BD13&", n="&'Base de datos'!BC13&")",IF('Base de datos'!BB13="","",'Base de datos'!BB13)) | I13: =IF('Base de datos'!BG13="","",'Base de datos'!BG13) | J13: =_xlfn.TEXTJOIN(", ",TRUE(),IF('Base de datos'!BB13="Sí","Monte Carlo",""),IF('Base de datos'!BM13="Sí","HIL",""),IF('Base de datos'!BL13="Sí","Robustez analítica","")) | K13: =IF('Base de datos'!BM13="","",'Base de datos'!BM13) | L13: =IF('Base de datos'!BS13="","",'Base de datos'!BS13)
A14: =IF('Base de datos'!A14="","",'Base de datos'!A14) | B14: =IF('Base de datos'!C14="","",'Base de datos'!C14) | C14: =IF('Base de datos'!K14="","",'Base de datos'!K14) | D14: =IF('Base de datos'!BH14="","",'Base de datos'!BH14) | E14: =_xlfn.TEXTJOIN(", ",TRUE(),IF('Base de datos'!$AM$14="Sí","Masa",""),IF('Base de datos'!$AN$14="Sí","Centro de gravedad",""),IF('Base de datos'!$AO$14="Sí","Momentos de inercia",""),IF('Base de datos'!$AP$14="Sí","Coeficientes aerodinámicos",""),IF('Base de datos'!$AQ$14="Sí","Empuje",""),IF('Base de datos'!$AR$14="Sí","Actuadores",""),IF('Base de datos'!$AS$14="Sí","Sensores",""),IF('Base de datos'!$AT$14="Sí","Viento",""),IF('Base de datos'!$AU$14="Sí","Turbulencia",""),IF('Base de datos'!$AV$14="Sí","Dinámicas no modeladas",""),IF('Base de datos'!$AW$14="Sí","Otros","")) | F14: =IF('Base de datos'!AY14="","",'Base de datos'!AY14) | G14: =IF('Base de datos'!AZ14="","",'Base de datos'!AZ14) | H14: =IF('Base de datos'!BB14="Sí","Sí ("&'Base de datos'!BD14&", n="&'Base de datos'!BC14&")",IF('Base de datos'!BB14="","",'Base de datos'!BB14)) | I14: =IF('Base de datos'!BG14="","",'Base de datos'!BG14) | J14: =_xlfn.TEXTJOIN(", ",TRUE(),IF('Base de datos'!BB14="Sí","Monte Carlo",""),IF('Base de datos'!BM14="Sí","HIL",""),IF('Base de datos'!BL14="Sí","Robustez analítica","")) | K14: =IF('Base de datos'!BM14="","",'Base de datos'!BM14) | L14: =IF('Base de datos'!BS14="","",'Base de datos'!BS14)
A15: =IF('Base de datos'!A15="","",'Base de datos'!A15) | B15: =IF('Base de datos'!C15="","",'Base de datos'!C15) | C15: =IF('Base de datos'!K15="","",'Base de datos'!K15) | D15: =IF('Base de datos'!BH15="","",'Base de datos'!BH15) | E15: =_xlfn.TEXTJOIN(", ",TRUE(),IF('Base de datos'!$AM$15="Sí","Masa",""),IF('Base de datos'!$AN$15="Sí","Centro de gravedad",""),IF('Base de datos'!$AO$15="Sí","Momentos de inercia",""),IF('Base de datos'!$AP$15="Sí","Coeficientes aerodinámicos",""),IF('Base de datos'!$AQ$15="Sí","Empuje",""),IF('Base de datos'!$AR$15="Sí","Actuadores",""),IF('Base de datos'!$AS$15="Sí","Sensores",""),IF('Base de datos'!$AT$15="Sí","Viento",""),IF('Base de datos'!$AU$15="Sí","Turbulencia",""),IF('Base de datos'!$AV$15="Sí","Dinámicas no modeladas",""),IF('Base de datos'!$AW$15="Sí","Otros","")) | F15: =IF('Base de datos'!AY15="","",'Base de datos'!AY15) | G15: =IF('Base de datos'!AZ15="","",'Base de datos'!AZ15) | H15: =IF('Base de datos'!BB15="Sí","Sí ("&'Base de datos'!BD15&", n="&'Base de datos'!BC15&")",IF('Base de datos'!BB15="","",'Base de datos'!BB15)) | I15: =IF('Base de datos'!BG15="","",'Base de datos'!BG15) | J15: =_xlfn.TEXTJOIN(", ",TRUE(),IF('Base de datos'!BB15="Sí","Monte Carlo",""),IF('Base de datos'!BM15="Sí","HIL",""),IF('Base de datos'!BL15="Sí","Robustez analítica","")) | K15: =IF('Base de datos'!BM15="","",'Base de datos'!BM15) | L15: =IF('Base de datos'!BS15="","",'Base de datos'!BS15)
A16: =IF('Base de datos'!A16="","",'Base de datos'!A16) | B16: =IF('Base de datos'!C16="","",'Base de datos'!C16) | C16: =IF('Base de datos'!K16="","",'Base de datos'!K16) | D16: =IF('Base de datos'!BH16="","",'Base de datos'!BH16) | E16: =_xlfn.TEXTJOIN(", ",TRUE(),IF('Base de datos'!$AM$16="Sí","Masa",""),IF('Base de datos'!$AN$16="Sí","Centro de gravedad",""),IF('Base de datos'!$AO$16="Sí","Momentos de inercia",""),IF('Base de datos'!$AP$16="Sí","Coeficientes aerodinámicos",""),IF('Base de datos'!$AQ$16="Sí","Empuje",""),IF('Base de datos'!$AR$16="Sí","Actuadores",""),IF('Base de datos'!$AS$16="Sí","Sensores",""),IF('Base de datos'!$AT$16="Sí","Viento",""),IF('Base de datos'!$AU$16="Sí","Turbulencia",""),IF('Base de datos'!$AV$16="Sí","Dinámicas no modeladas",""),IF('Base de datos'!$AW$16="Sí","Otros","")) | F16: =IF('Base de datos'!AY16="","",'Base de datos'!AY16) | G16: =IF('Base de datos'!AZ16="","",'Base de datos'!AZ16) | H16: =IF('Base de datos'!BB16="Sí","Sí ("&'Base de datos'!BD16&", n="&'Base de datos'!BC16&")",IF('Base de datos'!BB16="","",'Base de datos'!BB16)) | I16: =IF('Base de datos'!BG16="","",'Base de datos'!BG16) | J16: =_xlfn.TEXTJOIN(", ",TRUE(),IF('Base de datos'!BB16="Sí","Monte Carlo",""),IF('Base de datos'!BM16="Sí","HIL",""),IF('Base de datos'!BL16="Sí","Robustez analítica","")) | K16: =IF('Base de datos'!BM16="","",'Base de datos'!BM16) | L16: =IF('Base de datos'!BS16="","",'Base de datos'!BS16)
A17: =IF('Base de datos'!A17="","",'Base de datos'!A17) | B17: =IF('Base de datos'!C17="","",'Base de datos'!C17) | C17: =IF('Base de datos'!K17="","",'Base de datos'!K17) | D17: =IF('Base de datos'!BH17="","",'Base de datos'!BH17) | E17: =_xlfn.TEXTJOIN(", ",TRUE(),IF('Base de datos'!$AM$17="Sí","Masa",""),IF('Base de datos'!$AN$17="Sí","Centro de gravedad",""),IF('Base de datos'!$AO$17="Sí","Momentos de inercia",""),IF('Base de datos'!$AP$17="Sí","Coeficientes aerodinámicos",""),IF('Base de datos'!$AQ$17="Sí","Empuje",""),IF('Base de datos'!$AR$17="Sí","Actuadores",""),IF('Base de datos'!$AS$17="Sí","Sensores",""),IF('Base de datos'!$AT$17="Sí","Viento",""),IF('Base de datos'!$AU$17="Sí","Turbulencia",""),IF('Base de datos'!$AV$17="Sí","Dinámicas no modeladas",""),IF('Base de datos'!$AW$17="Sí","Otros","")) | F17: =IF('Base de datos'!AY17="","",'Base de datos'!AY17) | G17: =IF('Base de datos'!AZ17="","",'Base de datos'!AZ17) | H17: =IF('Base de datos'!BB17="Sí","Sí ("&'Base de datos'!BD17&", n="&'Base de datos'!BC17&")",IF('Base de datos'!BB17="","",'Base de datos'!BB17)) | I17: =IF('Base de datos'!BG17="","",'Base de datos'!BG17) | J17: =_xlfn.TEXTJOIN(", ",TRUE(),IF('Base de datos'!BB17="Sí","Monte Carlo",""),IF('Base de datos'!BM17="Sí","HIL",""),IF('Base de datos'!BL17="Sí","Robustez analítica","")) | K17: =IF('Base de datos'!BM17="","",'Base de datos'!BM17) | L17: =IF('Base de datos'!BS17="","",'Base de datos'!BS17)
A18: =IF('Base de datos'!A18="","",'Base de datos'!A18) | B18: =IF('Base de datos'!C18="","",'Base de datos'!C18) | C18: =IF('Base de datos'!K18="","",'Base de datos'!K18) | D18: =IF('Base de datos'!BH18="","",'Base de datos'!BH18) | E18: =_xlfn.TEXTJOIN(", ",TRUE(),IF('Base de datos'!$AM$18="Sí","Masa",""),IF('Base de datos'!$AN$18="Sí","Centro de gravedad",""),IF('Base de datos'!$AO$18="Sí","Momentos de inercia",""),IF('Base de datos'!$AP$18="Sí","Coeficientes aerodinámicos",""),IF('Base de datos'!$AQ$18="Sí","Empuje",""),IF('Base de datos'!$AR$18="Sí","Actuadores",""),IF('Base de datos'!$AS$18="Sí","Sensores",""),IF('Base de datos'!$AT$18="Sí","Viento",""),IF('Base de datos'!$AU$18="Sí","Turbulencia",""),IF('Base de datos'!$AV$18="Sí","Dinámicas no modeladas",""),IF('Base de datos'!$AW$18="Sí","Otros","")) | F18: =IF('Base de datos'!AY18="","",'Base de datos'!AY18) | G18: =IF('Base de datos'!AZ18="","",'Base de datos'!AZ18) | H18: =IF('Base de datos'!BB18="Sí","Sí ("&'Base de datos'!BD18&", n="&'Base de datos'!BC18&")",IF('Base de datos'!BB18="","",'Base de datos'!BB18)) | I18: =IF('Base de datos'!BG18="","",'Base de datos'!BG18) | J18: =_xlfn.TEXTJOIN(", ",TRUE(),IF('Base de datos'!BB18="Sí","Monte Carlo",""),IF('Base de datos'!BM18="Sí","HIL",""),IF('Base de datos'!BL18="Sí","Robustez analítica","")) | K18: =IF('Base de datos'!BM18="","",'Base de datos'!BM18) | L18: =IF('Base de datos'!BS18="","",'Base de datos'!BS18)
A19: =IF('Base de datos'!A19="","",'Base de datos'!A19) | B19: =IF('Base de datos'!C19="","",'Base de datos'!C19) | C19: =IF('Base de datos'!K19="","",'Base de datos'!K19) | D19: =IF('Base de datos'!BH19="","",'Base de datos'!BH19) | E19: =_xlfn.TEXTJOIN(", ",TRUE(),IF('Base de datos'!$AM$19="Sí","Masa",""),IF('Base de datos'!$AN$19="Sí","Centro de gravedad",""),IF('Base de datos'!$AO$19="Sí","Momentos de inercia",""),IF('Base de datos'!$AP$19="Sí","Coeficientes aerodinámicos",""),IF('Base de datos'!$AQ$19="Sí","Empuje",""),IF('Base de datos'!$AR$19="Sí","Actuadores",""),IF('Base de datos'!$AS$19="Sí","Sensores",""),IF('Base de datos'!$AT$19="Sí","Viento",""),IF('Base de datos'!$AU$19="Sí","Turbulencia",""),IF('Base de datos'!$AV$19="Sí","Dinámicas no modeladas",""),IF('Base de datos'!$AW$19="Sí","Otros","")) | F19: =IF('Base de datos'!AY19="","",'Base de datos'!AY19) | G19: =IF('Base de datos'!AZ19="","",'Base de datos'!AZ19) | H19: =IF('Base de datos'!BB19="Sí","Sí ("&'Base de datos'!BD19&", n="&'Base de datos'!BC19&")",IF('Base de datos'!BB19="","",'Base de datos'!BB19)) | I19: =IF('Base de datos'!BG19="","",'Base de datos'!BG19) | J19: =_xlfn.TEXTJOIN(", ",TRUE(),IF('Base de datos'!BB19="Sí","Monte Carlo",""),IF('Base de datos'!BM19="Sí","HIL",""),IF('Base de datos'!BL19="Sí","Robustez analítica","")) | K19: =IF('Base de datos'!BM19="","",'Base de datos'!BM19) | L19: =IF('Base de datos'!BS19="","",'Base de datos'!BS19)
A20: =IF('Base de datos'!A20="","",'Base de datos'!A20) | B20: =IF('Base de datos'!C20="","",'Base de datos'!C20) | C20: =IF('Base de datos'!K20="","",'Base de datos'!K20) | D20: =IF('Base de datos'!BH20="","",'Base de datos'!BH20) | E20: =_xlfn.TEXTJOIN(", ",TRUE(),IF('Base de datos'!$AM$20="Sí","Masa",""),IF('Base de datos'!$AN$20="Sí","Centro de gravedad",""),IF('Base de datos'!$AO$20="Sí","Momentos de inercia",""),IF('Base de datos'!$AP$20="Sí","Coeficientes aerodinámicos",""),IF('Base de datos'!$AQ$20="Sí","Empuje",""),IF('Base de datos'!$AR$20="Sí","Actuadores",""),IF('Base de datos'!$AS$20="Sí","Sensores",""),IF('Base de datos'!$AT$20="Sí","Viento",""),IF('Base de datos'!$AU$20="Sí","Turbulencia",""),IF('Base de datos'!$AV$20="Sí","Dinámicas no modeladas",""),IF('Base de datos'!$AW$20="Sí","Otros","")) | F20: =IF('Base de datos'!AY20="","",'Base de datos'!AY20) | G20: =IF('Base de datos'!AZ20="","",'Base de datos'!AZ20) | H20: =IF('Base de datos'!BB20="Sí","Sí ("&'Base de datos'!BD20&", n="&'Base de datos'!BC20&")",IF('Base de datos'!BB20="","",'Base de datos'!BB20)) | I20: =IF('Base de datos'!BG20="","",'Base de datos'!BG20) | J20: =_xlfn.TEXTJOIN(", ",TRUE(),IF('Base de datos'!BB20="Sí","Monte Carlo",""),IF('Base de datos'!BM20="Sí","HIL",""),IF('Base de datos'!BL20="Sí","Robustez analítica","")) | K20: =IF('Base de datos'!BM20="","",'Base de datos'!BM20) | L20: =IF('Base de datos'!BS20="","",'Base de datos'!BS20)
A21: =IF('Base de datos'!A21="","",'Base de datos'!A21) | B21: =IF('Base de datos'!C21="","",'Base de datos'!C21) | C21: =IF('Base de datos'!K21="","",'Base de datos'!K21) | D21: =IF('Base de datos'!BH21="","",'Base de datos'!BH21) | E21: =_xlfn.TEXTJOIN(", ",TRUE(),IF('Base de datos'!$AM$21="Sí","Masa",""),IF('Base de datos'!$AN$21="Sí","Centro de gravedad",""),IF('Base de datos'!$AO$21="Sí","Momentos de inercia",""),IF('Base de datos'!$AP$21="Sí","Coeficientes aerodinámicos",""),IF('Base de datos'!$AQ$21="Sí","Empuje",""),IF('Base de datos'!$AR$21="Sí","Actuadores",""),IF('Base de datos'!$AS$21="Sí","Sensores",""),IF('Base de datos'!$AT$21="Sí","Viento",""),IF('Base de datos'!$AU$21="Sí","Turbulencia",""),IF('Base de datos'!$AV$21="Sí","Dinámicas no modeladas",""),IF('Base de datos'!$AW$21="Sí","Otros","")) | F21: =IF('Base de datos'!AY21="","",'Base de datos'!AY21) | G21: =IF('Base de datos'!AZ21="","",'Base de datos'!AZ21) | H21: =IF('Base de datos'!BB21="Sí","Sí ("&'Base de datos'!BD21&", n="&'Base de datos'!BC21&")",IF('Base de datos'!BB21="","",'Base de datos'!BB21)) | I21: =IF('Base de datos'!BG21="","",'Base de datos'!BG21) | J21: =_xlfn.TEXTJOIN(", ",TRUE(),IF('Base de datos'!BB21="Sí","Monte Carlo",""),IF('Base de datos'!BM21="Sí","HIL",""),IF('Base de datos'!BL21="Sí","Robustez analítica","")) | K21: =IF('Base de datos'!BM21="","",'Base de datos'!BM21) | L21: =IF('Base de datos'!BS21="","",'Base de datos'!BS21)
A22: =IF('Base de datos'!A22="","",'Base de datos'!A22) | B22: =IF('Base de datos'!C22="","",'Base de datos'!C22) | C22: =IF('Base de datos'!K22="","",'Base de datos'!K22) | D22: =IF('Base de datos'!BH22="","",'Base de datos'!BH22) | E22: =_xlfn.TEXTJOIN(", ",TRUE(),IF('Base de datos'!$AM$22="Sí","Masa",""),IF('Base de datos'!$AN$22="Sí","Centro de gravedad",""),IF('Base de datos'!$AO$22="Sí","Momentos de inercia",""),IF('Base de datos'!$AP$22="Sí","Coeficientes aerodinámicos",""),IF('Base de datos'!$AQ$22="Sí","Empuje",""),IF('Base de datos'!$AR$22="Sí","Actuadores",""),IF('Base de datos'!$AS$22="Sí","Sensores",""),IF('Base de datos'!$AT$22="Sí","Viento",""),IF('Base de datos'!$AU$22="Sí","Turbulencia",""),IF('Base de datos'!$AV$22="Sí","Dinámicas no modeladas",""),IF('Base de datos'!$AW$22="Sí","Otros","")) | F22: =IF('Base de datos'!AY22="","",'Base de datos'!AY22) | G22: =IF('Base de datos'!AZ22="","",'Base de datos'!AZ22) | H22: =IF('Base de datos'!BB22="Sí","Sí ("&'Base de datos'!BD22&", n="&'Base de datos'!BC22&")",IF('Base de datos'!BB22="","",'Base de datos'!BB22)) | I22: =IF('Base de datos'!BG22="","",'Base de datos'!BG22) | J22: =_xlfn.TEXTJOIN(", ",TRUE(),IF('Base de datos'!BB22="Sí","Monte Carlo",""),IF('Base de datos'!BM22="Sí","HIL",""),IF('Base de datos'!BL22="Sí","Robustez analítica","")) | K22: =IF('Base de datos'!BM22="","",'Base de datos'!BM22) | L22: =IF('Base de datos'!BS22="","",'Base de datos'!BS22)
A23: =IF('Base de datos'!A23="","",'Base de datos'!A23) | B23: =IF('Base de datos'!C23="","",'Base de datos'!C23) | C23: =IF('Base de datos'!K23="","",'Base de datos'!K23) | D23: =IF('Base de datos'!BH23="","",'Base de datos'!BH23) | E23: =_xlfn.TEXTJOIN(", ",TRUE(),IF('Base de datos'!$AM$23="Sí","Masa",""),IF('Base de datos'!$AN$23="Sí","Centro de gravedad",""),IF('Base de datos'!$AO$23="Sí","Momentos de inercia",""),IF('Base de datos'!$AP$23="Sí","Coeficientes aerodinámicos",""),IF('Base de datos'!$AQ$23="Sí","Empuje",""),IF('Base de datos'!$AR$23="Sí","Actuadores",""),IF('Base de datos'!$AS$23="Sí","Sensores",""),IF('Base de datos'!$AT$23="Sí","Viento",""),IF('Base de datos'!$AU$23="Sí","Turbulencia",""),IF('Base de datos'!$AV$23="Sí","Dinámicas no modeladas",""),IF('Base de datos'!$AW$23="Sí","Otros","")) | F23: =IF('Base de datos'!AY23="","",'Base de datos'!AY23) | G23: =IF('Base de datos'!AZ23="","",'Base de datos'!AZ23) | H23: =IF('Base de datos'!BB23="Sí","Sí ("&'Base de datos'!BD23&", n="&'Base de datos'!BC23&")",IF('Base de datos'!BB23="","",'Base de datos'!BB23)) | I23: =IF('Base de datos'!BG23="","",'Base de datos'!BG23) | J23: =_xlfn.TEXTJOIN(", ",TRUE(),IF('Base de datos'!BB23="Sí","Monte Carlo",""),IF('Base de datos'!BM23="Sí","HIL",""),IF('Base de datos'!BL23="Sí","Robustez analítica","")) | K23: =IF('Base de datos'!BM23="","",'Base de datos'!BM23) | L23: =IF('Base de datos'!BS23="","",'Base de datos'!BS23)
A24: =IF('Base de datos'!A24="","",'Base de datos'!A24) | B24: =IF('Base de datos'!C24="","",'Base de datos'!C24) | C24: =IF('Base de datos'!K24="","",'Base de datos'!K24) | D24: =IF('Base de datos'!BH24="","",'Base de datos'!BH24) | E24: =_xlfn.TEXTJOIN(", ",TRUE(),IF('Base de datos'!$AM$24="Sí","Masa",""),IF('Base de datos'!$AN$24="Sí","Centro de gravedad",""),IF('Base de datos'!$AO$24="Sí","Momentos de inercia",""),IF('Base de datos'!$AP$24="Sí","Coeficientes aerodinámicos",""),IF('Base de datos'!$AQ$24="Sí","Empuje",""),IF('Base de datos'!$AR$24="Sí","Actuadores",""),IF('Base de datos'!$AS$24="Sí","Sensores",""),IF('Base de datos'!$AT$24="Sí","Viento",""),IF('Base de datos'!$AU$24="Sí","Turbulencia",""),IF('Base de datos'!$AV$24="Sí","Dinámicas no modeladas",""),IF('Base de datos'!$AW$24="Sí","Otros","")) | F24: =IF('Base de datos'!AY24="","",'Base de datos'!AY24) | G24: =IF('Base de datos'!AZ24="","",'Base de datos'!AZ24) | H24: =IF('Base de datos'!BB24="Sí","Sí ("&'Base de datos'!BD24&", n="&'Base de datos'!BC24&")",IF('Base de datos'!BB24="","",'Base de datos'!BB24)) | I24: =IF('Base de datos'!BG24="","",'Base de datos'!BG24) | J24: =_xlfn.TEXTJOIN(", ",TRUE(),IF('Base de datos'!BB24="Sí","Monte Carlo",""),IF('Base de datos'!BM24="Sí","HIL",""),IF('Base de datos'!BL24="Sí","Robustez analítica","")) | K24: =IF('Base de datos'!BM24="","",'Base de datos'!BM24) | L24: =IF('Base de datos'!BS24="","",'Base de datos'!BS24)
A25: =IF('Base de datos'!A25="","",'Base de datos'!A25) | B25: =IF('Base de datos'!C25="","",'Base de datos'!C25) | C25: =IF('Base de datos'!K25="","",'Base de datos'!K25) | D25: =IF('Base de datos'!BH25="","",'Base de datos'!BH25) | E25: =_xlfn.TEXTJOIN(", ",TRUE(),IF('Base de datos'!$AM$25="Sí","Masa",""),IF('Base de datos'!$AN$25="Sí","Centro de gravedad",""),IF('Base de datos'!$AO$25="Sí","Momentos de inercia",""),IF('Base de datos'!$AP$25="Sí","Coeficientes aerodinámicos",""),IF('Base de datos'!$AQ$25="Sí","Empuje",""),IF('Base de datos'!$AR$25="Sí","Actuadores",""),IF('Base de datos'!$AS$25="Sí","Sensores",""),IF('Base de datos'!$AT$25="Sí","Viento",""),IF('Base de datos'!$AU$25="Sí","Turbulencia",""),IF('Base de datos'!$AV$25="Sí","Dinámicas no modeladas",""),IF('Base de datos'!$AW$25="Sí","Otros","")) | F25: =IF('Base de datos'!AY25="","",'Base de datos'!AY25) | G25: =IF('Base de datos'!AZ25="","",'Base de datos'!AZ25) | H25: =IF('Base de datos'!BB25="Sí","Sí ("&'Base de datos'!BD25&", n="&'Base de datos'!BC25&")",IF('Base de datos'!BB25="","",'Base de datos'!BB25)) | I25: =IF('Base de datos'!BG25="","",'Base de datos'!BG25) | J25: =_xlfn.TEXTJOIN(", ",TRUE(),IF('Base de datos'!BB25="Sí","Monte Carlo",""),IF('Base de datos'!BM25="Sí","HIL",""),IF('Base de datos'!BL25="Sí","Robustez analítica","")) | K25: =IF('Base de datos'!BM25="","",'Base de datos'!BM25) | L25: =IF('Base de datos'!BS25="","",'Base de datos'!BS25)
A26: =IF('Base de datos'!A26="","",'Base de datos'!A26) | B26: =IF('Base de datos'!C26="","",'Base de datos'!C26) | C26: =IF('Base de datos'!K26="","",'Base de datos'!K26) | D26: =IF('Base de datos'!BH26="","",'Base de datos'!BH26) | E26: =_xlfn.TEXTJOIN(", ",TRUE(),IF('Base de datos'!$AM$26="Sí","Masa",""),IF('Base de datos'!$AN$26="Sí","Centro de gravedad",""),IF('Base de datos'!$AO$26="Sí","Momentos de inercia",""),IF('Base de datos'!$AP$26="Sí","Coeficientes aerodinámicos",""),IF('Base de datos'!$AQ$26="Sí","Empuje",""),IF('Base de datos'!$AR$26="Sí","Actuadores",""),IF('Base de datos'!$AS$26="Sí","Sensores",""),IF('Base de datos'!$AT$26="Sí","Viento",""),IF('Base de datos'!$AU$26="Sí","Turbulencia",""),IF('Base de datos'!$AV$26="Sí","Dinámicas no modeladas",""),IF('Base de datos'!$AW$26="Sí","Otros","")) | F26: =IF('Base de datos'!AY26="","",'Base de datos'!AY26) | G26: =IF('Base de datos'!AZ26="","",'Base de datos'!AZ26) | H26: =IF('Base de datos'!BB26="Sí","Sí ("&'Base de datos'!BD26&", n="&'Base de datos'!BC26&")",IF('Base de datos'!BB26="","",'Base de datos'!BB26)) | I26: =IF('Base de datos'!BG26="","",'Base de datos'!BG26) | J26: =_xlfn.TEXTJOIN(", ",TRUE(),IF('Base de datos'!BB26="Sí","Monte Carlo",""),IF('Base de datos'!BM26="Sí","HIL",""),IF('Base de datos'!BL26="Sí","Robustez analítica","")) | K26: =IF('Base de datos'!BM26="","",'Base de datos'!BM26) | L26: =IF('Base de datos'!BS26="","",'Base de datos'!BS26)
A27: =IF('Base de datos'!A27="","",'Base de datos'!A27) | B27: =IF('Base de datos'!C27="","",'Base de datos'!C27) | C27: =IF('Base de datos'!K27="","",'Base de datos'!K27) | D27: =IF('Base de datos'!BH27="","",'Base de datos'!BH27) | E27: =_xlfn.TEXTJOIN(", ",TRUE(),IF('Base de datos'!$AM$27="Sí","Masa",""),IF('Base de datos'!$AN$27="Sí","Centro de gravedad",""),IF('Base de datos'!$AO$27="Sí","Momentos de inercia",""),IF('Base de datos'!$AP$27="Sí","Coeficientes aerodinámicos",""),IF('Base de datos'!$AQ$27="Sí","Empuje",""),IF('Base de datos'!$AR$27="Sí","Actuadores",""),IF('Base de datos'!$AS$27="Sí","Sensores",""),IF('Base de datos'!$AT$27="Sí","Viento",""),IF('Base de datos'!$AU$27="Sí","Turbulencia",""),IF('Base de datos'!$AV$27="Sí","Dinámicas no modeladas",""),IF('Base de datos'!$AW$27="Sí","Otros","")) | F27: =IF('Base de datos'!AY27="","",'Base de datos'!AY27) | G27: =IF('Base de datos'!AZ27="","",'Base de datos'!AZ27) | H27: =IF('Base de datos'!BB27="Sí","Sí ("&'Base de datos'!BD27&", n="&'Base de datos'!BC27&")",IF('Base de datos'!BB27="","",'Base de datos'!BB27)) | I27: =IF('Base de datos'!BG27="","",'Base de datos'!BG27) | J27: =_xlfn.TEXTJOIN(", ",TRUE(),IF('Base de datos'!BB27="Sí","Monte Carlo",""),IF('Base de datos'!BM27="Sí","HIL",""),IF('Base de datos'!BL27="Sí","Robustez analítica","")) | K27: =IF('Base de datos'!BM27="","",'Base de datos'!BM27) | L27: =IF('Base de datos'!BS27="","",'Base de datos'!BS27)
A28: =IF('Base de datos'!A28="","",'Base de datos'!A28) | B28: =IF('Base de datos'!C28="","",'Base de datos'!C28) | C28: =IF('Base de datos'!K28="","",'Base de datos'!K28) | D28: =IF('Base de datos'!BH28="","",'Base de datos'!BH28) | E28: =_xlfn.TEXTJOIN(", ",TRUE(),IF('Base de datos'!$AM$28="Sí","Masa",""),IF('Base de datos'!$AN$28="Sí","Centro de gravedad",""),IF('Base de datos'!$AO$28="Sí","Momentos de inercia",""),IF('Base de datos'!$AP$28="Sí","Coeficientes aerodinámicos",""),IF('Base de datos'!$AQ$28="Sí","Empuje",""),IF('Base de datos'!$AR$28="Sí","Actuadores",""),IF('Base de datos'!$AS$28="Sí","Sensores",""),IF('Base de datos'!$AT$28="Sí","Viento",""),IF('Base de datos'!$AU$28="Sí","Turbulencia",""),IF('Base de datos'!$AV$28="Sí","Dinámicas no modeladas",""),IF('Base de datos'!$AW$28="Sí","Otros","")) | F28: =IF('Base de datos'!AY28="","",'Base de datos'!AY28) | G28: =IF('Base de datos'!AZ28="","",'Base de datos'!AZ28) | H28: =IF('Base de datos'!BB28="Sí","Sí ("&'Base de datos'!BD28&", n="&'Base de datos'!BC28&")",IF('Base de datos'!BB28="","",'Base de datos'!BB28)) | I28: =IF('Base de datos'!BG28="","",'Base de datos'!BG28) | J28: =_xlfn.TEXTJOIN(", ",TRUE(),IF('Base de datos'!BB28="Sí","Monte Carlo",""),IF('Base de datos'!BM28="Sí","HIL",""),IF('Base de datos'!BL28="Sí","Robustez analítica","")) | K28: =IF('Base de datos'!BM28="","",'Base de datos'!BM28) | L28: =IF('Base de datos'!BS28="","",'Base de datos'!BS28)
A29: =IF('Base de datos'!A29="","",'Base de datos'!A29) | B29: =IF('Base de datos'!C29="","",'Base de datos'!C29) | C29: =IF('Base de datos'!K29="","",'Base de datos'!K29) | D29: =IF('Base de datos'!BH29="","",'Base de datos'!BH29) | E29: =_xlfn.TEXTJOIN(", ",TRUE(),IF('Base de datos'!$AM$29="Sí","Masa",""),IF('Base de datos'!$AN$29="Sí","Centro de gravedad",""),IF('Base de datos'!$AO$29="Sí","Momentos de inercia",""),IF('Base de datos'!$AP$29="Sí","Coeficientes aerodinámicos",""),IF('Base de datos'!$AQ$29="Sí","Empuje",""),IF('Base de datos'!$AR$29="Sí","Actuadores",""),IF('Base de datos'!$AS$29="Sí","Sensores",""),IF('Base de datos'!$AT$29="Sí","Viento",""),IF('Base de datos'!$AU$29="Sí","Turbulencia",""),IF('Base de datos'!$AV$29="Sí","Dinámicas no modeladas",""),IF('Base de datos'!$AW$29="Sí","Otros","")) | F29: =IF('Base de datos'!AY29="","",'Base de datos'!AY29) | G29: =IF('Base de datos'!AZ29="","",'Base de datos'!AZ29) | H29: =IF('Base de datos'!BB29="Sí","Sí ("&'Base de datos'!BD29&", n="&'Base de datos'!BC29&")",IF('Base de datos'!BB29="","",'Base de datos'!BB29)) | I29: =IF('Base de datos'!BG29="","",'Base de datos'!BG29) | J29: =_xlfn.TEXTJOIN(", ",TRUE(),IF('Base de datos'!BB29="Sí","Monte Carlo",""),IF('Base de datos'!BM29="Sí","HIL",""),IF('Base de datos'!BL29="Sí","Robustez analítica","")) | K29: =IF('Base de datos'!BM29="","",'Base de datos'!BM29) | L29: =IF('Base de datos'!BS29="","",'Base de datos'!BS29)
A30: =IF('Base de datos'!A30="","",'Base de datos'!A30) | B30: =IF('Base de datos'!C30="","",'Base de datos'!C30) | C30: =IF('Base de datos'!K30="","",'Base de datos'!K30) | D30: =IF('Base de datos'!BH30="","",'Base de datos'!BH30) | E30: =_xlfn.TEXTJOIN(", ",TRUE(),IF('Base de datos'!$AM$30="Sí","Masa",""),IF('Base de datos'!$AN$30="Sí","Centro de gravedad",""),IF('Base de datos'!$AO$30="Sí","Momentos de inercia",""),IF('Base de datos'!$AP$30="Sí","Coeficientes aerodinámicos",""),IF('Base de datos'!$AQ$30="Sí","Empuje",""),IF('Base de datos'!$AR$30="Sí","Actuadores",""),IF('Base de datos'!$AS$30="Sí","Sensores",""),IF('Base de datos'!$AT$30="Sí","Viento",""),IF('Base de datos'!$AU$30="Sí","Turbulencia",""),IF('Base de datos'!$AV$30="Sí","Dinámicas no modeladas",""),IF('Base de datos'!$AW$30="Sí","Otros","")) | F30: =IF('Base de datos'!AY30="","",'Base de datos'!AY30) | G30: =IF('Base de datos'!AZ30="","",'Base de datos'!AZ30) | H30: =IF('Base de datos'!BB30="Sí","Sí ("&'Base de datos'!BD30&", n="&'Base de datos'!BC30&")",IF('Base de datos'!BB30="","",'Base de datos'!BB30)) | I30: =IF('Base de datos'!BG30="","",'Base de datos'!BG30) | J30: =_xlfn.TEXTJOIN(", ",TRUE(),IF('Base de datos'!BB30="Sí","Monte Carlo",""),IF('Base de datos'!BM30="Sí","HIL",""),IF('Base de datos'!BL30="Sí","Robustez analítica","")) | K30: =IF('Base de datos'!BM30="","",'Base de datos'!BM30) | L30: =IF('Base de datos'!BS30="","",'Base de datos'!BS30)
A31: =IF('Base de datos'!A31="","",'Base de datos'!A31) | B31: =IF('Base de datos'!C31="","",'Base de datos'!C31) | C31: =IF('Base de datos'!K31="","",'Base de datos'!K31) | D31: =IF('Base de datos'!BH31="","",'Base de datos'!BH31) | E31: =_xlfn.TEXTJOIN(", ",TRUE(),IF('Base de datos'!$AM$31="Sí","Masa",""),IF('Base de datos'!$AN$31="Sí","Centro de gravedad",""),IF('Base de datos'!$AO$31="Sí","Momentos de inercia",""),IF('Base de datos'!$AP$31="Sí","Coeficientes aerodinámicos",""),IF('Base de datos'!$AQ$31="Sí","Empuje",""),IF('Base de datos'!$AR$31="Sí","Actuadores",""),IF('Base de datos'!$AS$31="Sí","Sensores",""),IF('Base de datos'!$AT$31="Sí","Viento",""),IF('Base de datos'!$AU$31="Sí","Turbulencia",""),IF('Base de datos'!$AV$31="Sí","Dinámicas no modeladas",""),IF('Base de datos'!$AW$31="Sí","Otros","")) | F31: =IF('Base de datos'!AY31="","",'Base de datos'!AY31) | G31: =IF('Base de datos'!AZ31="","",'Base de datos'!AZ31) | H31: =IF('Base de datos'!BB31="Sí","Sí ("&'Base de datos'!BD31&", n="&'Base de datos'!BC31&")",IF('Base de datos'!BB31="","",'Base de datos'!BB31)) | I31: =IF('Base de datos'!BG31="","",'Base de datos'!BG31) | J31: =_xlfn.TEXTJOIN(", ",TRUE(),IF('Base de datos'!BB31="Sí","Monte Carlo",""),IF('Base de datos'!BM31="Sí","HIL",""),IF('Base de datos'!BL31="Sí","Robustez analítica","")) | K31: =IF('Base de datos'!BM31="","",'Base de datos'!BM31) | L31: =IF('Base de datos'!BS31="","",'Base de datos'!BS31)
A32: =IF('Base de datos'!A32="","",'Base de datos'!A32) | B32: =IF('Base de datos'!C32="","",'Base de datos'!C32) | C32: =IF('Base de datos'!K32="","",'Base de datos'!K32) | D32: =IF('Base de datos'!BH32="","",'Base de datos'!BH32) | E32: =_xlfn.TEXTJOIN(", ",TRUE(),IF('Base de datos'!$AM$32="Sí","Masa",""),IF('Base de datos'!$AN$32="Sí","Centro de gravedad",""),IF('Base de datos'!$AO$32="Sí","Momentos de inercia",""),IF('Base de datos'!$AP$32="Sí","Coeficientes aerodinámicos",""),IF('Base de datos'!$AQ$32="Sí","Empuje",""),IF('Base de datos'!$AR$32="Sí","Actuadores",""),IF('Base de datos'!$AS$32="Sí","Sensores",""),IF('Base de datos'!$AT$32="Sí","Viento",""),IF('Base de datos'!$AU$32="Sí","Turbulencia",""),IF('Base de datos'!$AV$32="Sí","Dinámicas no modeladas",""),IF('Base de datos'!$AW$32="Sí","Otros","")) | F32: =IF('Base de datos'!AY32="","",'Base de datos'!AY32) | G32: =IF('Base de datos'!AZ32="","",'Base de datos'!AZ32) | H32: =IF('Base de datos'!BB32="Sí","Sí ("&'Base de datos'!BD32&", n="&'Base de datos'!BC32&")",IF('Base de datos'!BB32="","",'Base de datos'!BB32)) | I32: =IF('Base de datos'!BG32="","",'Base de datos'!BG32) | J32: =_xlfn.TEXTJOIN(", ",TRUE(),IF('Base de datos'!BB32="Sí","Monte Carlo",""),IF('Base de datos'!BM32="Sí","HIL",""),IF('Base de datos'!BL32="Sí","Robustez analítica","")) | K32: =IF('Base de datos'!BM32="","",'Base de datos'!BM32) | L32: =IF('Base de datos'!BS32="","",'Base de datos'!BS32)
A33: =IF('Base de datos'!A33="","",'Base de datos'!A33) | B33: =IF('Base de datos'!C33="","",'Base de datos'!C33) | C33: =IF('Base de datos'!K33="","",'Base de datos'!K33) | D33: =IF('Base de datos'!BH33="","",'Base de datos'!BH33) | E33: =_xlfn.TEXTJOIN(", ",TRUE(),IF('Base de datos'!$AM$33="Sí","Masa",""),IF('Base de datos'!$AN$33="Sí","Centro de gravedad",""),IF('Base de datos'!$AO$33="Sí","Momentos de inercia",""),IF('Base de datos'!$AP$33="Sí","Coeficientes aerodinámicos",""),IF('Base de datos'!$AQ$33="Sí","Empuje",""),IF('Base de datos'!$AR$33="Sí","Actuadores",""),IF('Base de datos'!$AS$33="Sí","Sensores",""),IF('Base de datos'!$AT$33="Sí","Viento",""),IF('Base de datos'!$AU$33="Sí","Turbulencia",""),IF('Base de datos'!$AV$33="Sí","Dinámicas no modeladas",""),IF('Base de datos'!$AW$33="Sí","Otros","")) | F33: =IF('Base de datos'!AY33="","",'Base de datos'!AY33) | G33: =IF('Base de datos'!AZ33="","",'Base de datos'!AZ33) | H33: =IF('Base de datos'!BB33="Sí","Sí ("&'Base de datos'!BD33&", n="&'Base de datos'!BC33&")",IF('Base de datos'!BB33="","",'Base de datos'!BB33)) | I33: =IF('Base de datos'!BG33="","",'Base de datos'!BG33) | J33: =_xlfn.TEXTJOIN(", ",TRUE(),IF('Base de datos'!BB33="Sí","Monte Carlo",""),IF('Base de datos'!BM33="Sí","HIL",""),IF('Base de datos'!BL33="Sí","Robustez analítica","")) | K33: =IF('Base de datos'!BM33="","",'Base de datos'!BM33) | L33: =IF('Base de datos'!BS33="","",'Base de datos'!BS33)
